<?xml version="1.0" ?>
<robot name="Robot">
  <!--Generated by CROSS, a ROS Workbench for FreeCAD (https://github.com/galou/freecad.cross)-->
  <link name="Link">
    <visual>
      <!--main_body_parts001/Associated_Part_009.Part__Feature022.-->
      <origin xyz="0.0 0.0 0.0" rpy="0.0 -0.0 0.0"/>
      <geometry>
        <mesh filename="package://robot_model/meshes/ahilya_mini_shapes_Associated_Part_021.dae"/>
      </geometry>
    </visual>
    <visual>
      <!--main_body_parts001/Associated_Part_009.Part__Feature023.-->
      <origin xyz="0.0 0.0 0.0" rpy="0.0 -0.0 0.0"/>
      <geometry>
        <mesh filename="package://robot_model/meshes/ahilya_mini_shapes_Associated_Part_022.dae"/>
      </geometry>
    </visual>
    <visual>
      <!--main_body_parts001/Cut.-->
      <origin xyz="0.0 0.0 0.0" rpy="0.0 -0.0 0.0"/>
      <geometry>
        <mesh filename="package://robot_model/meshes/ahilya_mini_shapes_Cut.dae"/>
      </geometry>
    </visual>
    <collision>
      <!--main_body_parts001/Associated_Part_009.Part__Feature022.-->
      <origin xyz="0.0 0.0 0.0" rpy="0.0 -0.0 0.0"/>
      <geometry>
        <mesh filename="package://robot_model/meshes/ahilya_mini_shapes_Associated_Part_021.dae"/>
      </geometry>
    </collision>
    <collision>
      <!--main_body_parts001/Associated_Part_009.Part__Feature023.-->
      <origin xyz="0.0 0.0 0.0" rpy="0.0 -0.0 0.0"/>
      <geometry>
        <mesh filename="package://robot_model/meshes/ahilya_mini_shapes_Associated_Part_022.dae"/>
      </geometry>
    </collision>
    <collision>
      <!--main_body_parts001/Cut.-->
      <origin xyz="0.0 0.0 0.0" rpy="0.0 -0.0 0.0"/>
      <geometry>
        <mesh filename="package://robot_model/meshes/ahilya_mini_shapes_Cut.dae"/>
      </geometry>
    </collision>
    <inertial>
      <mass value="0.0"/>
      <origin xyz="0.0 0.0 0.0" rpy="0.0 -0.0 0.0"/>
      <inertia ixx="0.0" ixy="0.0" ixz="0.0" iyy="0.0" iyz="0.0" izz="0.0"/>
    </inertial>
  </link>
  <link name="Link001">
    <visual>
      <!--fins-->
      <origin xyz="0.0 0.0 0.0" rpy="0.0 -0.0 0.0"/>
      <geometry>
        <mesh filename="package://robot_model/meshes/ahilya_mini_shapes_fins.dae"/>
      </geometry>
    </visual>
    <collision>
      <!--fins-->
      <origin xyz="0.0 0.0 0.0" rpy="0.0 -0.0 0.0"/>
      <geometry>
        <mesh filename="package://robot_model/meshes/ahilya_mini_shapes_fins.dae"/>
      </geometry>
    </collision>
    <inertial>
      <mass value="0.0"/>
      <origin xyz="0.0 0.0 0.0" rpy="0.0 -0.0 0.0"/>
      <inertia ixx="0.0" ixy="0.0" ixz="0.0" iyy="0.0" iyz="0.0" izz="0.0"/>
    </inertial>
  </link>
  <link name="Link002">
    <visual>
      <!--fins (Mirror #1)-->
      <origin xyz="0.0 0.0 0.0" rpy="0.0 -0.0 0.0"/>
      <geometry>
        <mesh filename="package://robot_model/meshes/ahilya_mini_shapes_fins_Mirror_1_.dae"/>
      </geometry>
    </visual>
    <collision>
      <!--fins (Mirror #1)-->
      <origin xyz="0.0 0.0 0.0" rpy="0.0 -0.0 0.0"/>
      <geometry>
        <mesh filename="package://robot_model/meshes/ahilya_mini_shapes_fins_Mirror_1_.dae"/>
      </geometry>
    </collision>
    <inertial>
      <mass value="0.0"/>
      <origin xyz="0.0 0.0 0.0" rpy="0.0 -0.0 0.0"/>
      <inertia ixx="0.0" ixy="0.0" ixz="0.0" iyy="0.0" iyz="0.0" izz="0.0"/>
    </inertial>
  </link>
  <link name="Link003">
    <visual>
      <!--head-->
      <origin xyz="0.0 0.0 0.0" rpy="0.0 -0.0 0.0"/>
      <geometry>
        <mesh filename="package://robot_model/meshes/ahilya_mini_shapes_head.dae"/>
      </geometry>
    </visual>
    <collision>
      <!--head-->
      <origin xyz="0.0 0.0 0.0" rpy="0.0 -0.0 0.0"/>
      <geometry>
        <mesh filename="package://robot_model/meshes/ahilya_mini_shapes_head.dae"/>
      </geometry>
    </collision>
    <inertial>
      <mass value="0.0"/>
      <origin xyz="0.0 0.0 0.0" rpy="0.0 -0.0 0.0"/>
      <inertia ixx="0.0" ixy="0.0" ixz="0.0" iyy="0.0" iyz="0.0" izz="0.0"/>
    </inertial>
  </link>
  <joint name="Joint" type="continuous">
    <parent link="Link"/>
    <child link="Link002"/>
    <origin xyz="0.0 0.0 0.0" rpy="0.0 -0.0 0.0"/>
    <axis xyz="1 0 0"/>
  </joint>
  <joint name="Joint001" type="continuous">
    <parent link="Link"/>
    <child link="Link001"/>
    <origin xyz="0.0 0.0 0.0" rpy="0.0 -0.0 0.0"/>
    <axis xyz="1 0 0"/>
  </joint>
  <joint name="Joint002" type="continuous">
    <parent link="Link"/>
    <child link="Link003"/>
    <origin xyz="0.0 0.0 0.0" rpy="0.0 -0.0 0.0"/>
    <axis xyz="0 0 1"/>
  </joint>
</robot>
