<?xml version="1.0"?>

<robot name="differential_drive_robot" xmlns:xacro="http://www.ros.org/wiki/xacro">

    <!-- Robot Parameters -->
    <xacro:property name="PI" value="3.14159265" />
    <xacro:property name="body_length" value="0.5" />
    <xacro:property name="body_width" value="0.3" />
    <xacro:property name="body_height" value="0.1" />
    <xacro:property name="body_density" value="7850.0" /> <!-- Steel -->
    <xacro:property name="body_mass"
        value="${body_density * body_length * body_height * body_width}" />
    <xacro:property name="body_inertia_x"
        value="${1.0/12.0 * body_mass * (body_height*body_height + body_width*body_width)}" />
    <xacro:property name="body_inertia_y"
        value="${1.0/12.0 * body_mass * (body_length*body_length + body_height*body_height)}" />
    <xacro:property name="body_inertia_z"
        value="${1.0/12.0 * body_mass * (body_length*body_length + body_width*body_width)}" />


    <xacro:property name="wheel_radius" value="0.035" />
    <xacro:property name="wheel_width" value="0.03" />
    <xacro:property name="wheel_separation" value="${body_width + wheel_width}" />
    <xacro:property name="wheel_offset" value="${body_length/2 - wheel_radius}" />
    <xacro:property name="wheel_density" value="900" /> <!-- Ruber -->
    <xacro:property name="wheel_mass"
        value="${wheel_density * PI * wheel_radius * wheel_radius * wheel_width}" />
    <xacro:property name="wheel_inertia_x"
        value="${1.0/12.0 * wheel_mass * (3*wheel_radius*wheel_radius + wheel_width*wheel_width)}" />
    <xacro:property name="wheel_inertia_y"
        value="${1.0/12.0 * wheel_mass * (3*wheel_radius*wheel_radius + wheel_width*wheel_width)}" />
    <xacro:property name="wheel_inertia_z"
        value="${1.0/2.0 * wheel_mass * wheel_radius * wheel_radius}" />

    <xacro:property name="caster_radius" value="0.1" />
    <xacro:property name="caster_offset" value="${body_length/2 - caster_radius}" />
    <xacro:property name="caster_density" value="0.1" />
    <xacro:property name="caster_mass"
        value="${caster_density * 4.0/3.0 * PI * caster_radius * caster_radius * caster_radius}" />
    <xacro:property name="caster_inertia_x"
        value="${2.0/5.0 * caster_mass * caster_radius * caster_radius}" />
    <xacro:property name="caster_inertia_y"
        value="${2.0/5.0 * caster_mass * caster_radius * caster_radius}" />
    <xacro:property name="caster_inertia_z"
        value="${2.0/5.0 * caster_mass * caster_radius * caster_radius}" />

    <!-- Control Parameters -->
    <xacro:property name="max_linear_acceleration" value="10" />

    <!-- Links -->

    <!-- Body Link -->
    <!-- <link name="chassis">
        <visual>
            <origin xyz="0.0 0.0 0.0" rpy="0.0 0.0 0.0" />
            <geometry>
                <box size="${body_length} ${body_width} ${body_height}" />
            </geometry>
            <material name="body_material">
                <color rgba="0.25 0.25 0.25 1.0" />
            </material>
        </visual>
        <collision>
            <origin xyz="0.0 0.0 0.0" rpy="0.0 0.0 0.0" />
            <geometry>
                <box size="${body_length} ${body_width} ${body_height}" />
            </geometry>
        </collision>
        <inertial>
            <mass value="10" />
            <inertia ixx="${body_inertia_x}" ixy="0.0" ixz="0.0" iyy="${body_inertia_y}" iyz="0"
                izz="${body_inertia_z}" />
            <origin xyz="0 0 0" rpy="0 0 0" />
        </inertial>
    </link> -->









    <link name="wheel_left_link">
        <visual>
            <geometry>
                <cylinder radius="${wheel_radius}" length="${wheel_width}" />
            </geometry>
            <material name="wheel_material">
                <color rgba="0.0 0.0 0.0 1.0" />
            </material>
        </visual>
        <collision>
            <geometry>
                <cylinder radius="${wheel_radius}" length="${wheel_width}" />
            </geometry>
        </collision>
        <inertial>
            <mass value="2" />
            <inertia ixx="${wheel_inertia_x}" ixy="0.0" ixz="0.0" iyy="${wheel_inertia_y}" iyz="0"
                izz="${wheel_inertia_z}" />
            <origin xyz="0.0 0.0 0.0" rpy="1.570795 0.0 0.0" />
        </inertial>
    </link>


    <link name="wheel_right_link">
        <visual>
            <geometry>
                <cylinder radius="${wheel_radius}" length="${wheel_width}" />
            </geometry>
            <material name="wheel_material">
                <color rgba="0.0 0.0 0.0 1.0" />
            </material>
        </visual>
        <collision>
            <geometry>
                <cylinder radius="${wheel_radius}" length="${wheel_width}" />
            </geometry>
        </collision>
        <inertial>
            <mass value="2" />
            <inertia ixx="${wheel_inertia_x}" ixy="0.0" ixz="0.0" iyy="${wheel_inertia_y}" iyz="0"
                izz="${wheel_inertia_z}" />
            <origin xyz="0.0 0.0 0.0" rpy="1.570795 0.0 0.0" />
        </inertial>
    </link>



























  <link name="caster_front_link">
    <visual>
      <geometry>
        <sphere radius="0.01" />
      </geometry>
      <material name="blue" />
    </visual>
    <collision>
      <geometry>
        <sphere radius="0.01" />
      </geometry>
    </collision>
        <inertial>
            <mass value="1.1" />
            <inertia ixx="0.0" ixy="0.0" ixz="0.0" iyy="0.0" iyz="0"
                izz="0.0" />
            <origin xyz="0 0 0" rpy="0 0 0" />
        </inertial>
  </link>
  <link name="caster_rear_link">
    <visual>
      <geometry>
        <sphere radius="0.01" />
      </geometry>
      <material name="blue" />
    </visual>
    <collision>
      <geometry>
        <sphere radius="0.01" />
      </geometry>
    </collision>
        <inertial>
            <mass value="1.1" />
            <inertia ixx="0.0" ixy="0.0" ixz="0.0" iyy="0.0" iyz="0"
                izz="0.0" />
            <origin xyz="0 0 0" rpy="0 0 0" />
        </inertial>
  </link>
  <link name="caster_front_link_1">
    <visual>
      <geometry>
        <sphere radius="0.01" />
      </geometry>
      <material name="blue" />
    </visual>
    <collision>
      <geometry>
        <sphere radius="0.01" />
      </geometry>
    </collision>
        <inertial>
            <mass value="1.1" />
            <inertia ixx="0.0" ixy="0.0" ixz="0.0" iyy="0.0" iyz="0"
                izz="0.0" />
            <origin xyz="0 0 0" rpy="0 0 0" />
        </inertial>
  </link>
  <link name="caster_rear_link_1">
    <visual>
      <geometry>
        <sphere radius="0.01" />
      </geometry>
      <material name="blue" />
    </visual>
    <collision>
      <geometry>
        <sphere radius="0.01" />
      </geometry>
    </collision>
        <inertial>
            <mass value="1.1" />
            <inertia ixx="0.0" ixy="0.0" ixz="0.0" iyy="0.0" iyz="0"
                izz="0.0" />
            <origin xyz="0 0 0" rpy="0 0 0" />
        </inertial>
  </link>

  <!-- chassis ==to== caster wheel  -->
  <joint name="body_to_caster_wheel_Joint_1" type="fixed">
    <parent link="chassis" />
    <child link="caster_front_link" />
    <origin xyz="0.135 -0.101 -0.003" rpy="${pi/2} 0 0" />
    <axis xyz="0 0 1" />
  </joint>
  <joint name="body_to_caster_wheel_Joint_2" type="fixed">
    <parent link="chassis" />
    <child link="caster_rear_link" />
    <origin xyz="0.135 0.101 -0.003" rpy="${pi/2} 0 0" />
    <axis xyz="0 0 1" />
  </joint>
  <joint name="body_to_caster_wheel_Joint_3" type="fixed">
    <parent link="chassis" />
    <child link="caster_rear_link_1" />
    <origin xyz="-0.135 -0.101 -0.003" rpy="${pi/2} 0 0" />
    <axis xyz="0 0 1" />
  </joint>
  <joint name="body_to_caster_wheel_Joint_4" type="fixed">
    <parent link="chassis" />
    <child link="caster_front_link_1" />
    <origin xyz="-0.135 0.101 -0.003" rpy="${pi/2} 0 0" />
    <axis xyz="0 0 1" />
  </joint>






 <!-- chassis ==to== right tyre  -->
  <joint name="wheel_left_joint" type="continuous">
    <parent link="chassis" />
    <child link="wheel_left_link" />
    <origin xyz="0.0 0.1 0.022" rpy="-${pi/2} 0 0" />
    <axis xyz="0 0 1" />
        <limit effort="100" velocity="10.0"/>
        <dynamics damping="0.1" friction="0.1"/>
  </joint>
  <!-- chassis ==to== left tyre  -->
  <joint name="wheel_right_joint" type="continuous">
    <parent link="chassis" />
    <child link="wheel_right_link" />
    <origin xyz="0.0 -0.1 0.022" rpy="${pi/2} 0 0" />
    <axis xyz="0 0 -1" />
        <limit effort="100" velocity="10.0"/>
        <dynamics damping="0.1" friction="0.1"/>
  </joint>
  
  







  
    <!-- Gazebo Plugins -->
    <!-- <gazebo>
        <plugin filename="gz-sim-diff-drive-system" name="gz::sim::systems::DiffDrive">
            <right_joint>wheel_right_joint</right_joint>
            <left_joint>wheel_left_joint</left_joint>
            <wheel_separation>${wheel_separation}</wheel_separation>
            <wheel_radius>${wheel_radius}</wheel_radius>
            <max_linear_acceleration>${max_linear_acceleration}</max_linear_acceleration>
            <odom_publish_frequency>100</odom_publish_frequency>
            <topic>cmd_vel</topic>
            <odom_topic>odom</odom_topic>
        </plugin>

        <plugin filename="gz-sim-joint-state-publisher-system"
            name="gz::sim::systems::JointStatePublisher">
            <topic>joint_states</topic>
            <joint_name>wheel_right_joint</joint_name>
            <joint_name>wheel_left_joint</joint_name>
        </plugin>
    </gazebo> -->
    <!-- <gazebo>
        <plugin filename="gz-sim-diff-drive-system" name="gz::sim::systems::DiffDrive">
            <right_joint>wheel_right_joint</right_joint>
            <left_joint>wheel_left_joint</left_joint>
            <wheel_separation>0.2</wheel_separation>
            <wheel_radius>0.035</wheel_radius>
            <max_linear_acceleration>0.33</max_linear_acceleration>
            <odom_publish_frequency>100</odom_publish_frequency>
            <topic>cmd_vel</topic>
            <odom_topic>odom</odom_topic>
        </plugin>

        <plugin filename="gz-sim-joint-state-publisher-system" name="gz::sim::systems::JointStatePublisher">
            <topic>joint_states</topic>
            <joint_name>wheel_right_joint</joint_name>
            <joint_name>wheel_left_joint</joint_name>
        </plugin>
    </gazebo> -->


</robot>